/var/spool/slurm/d/job640713/slurm_script: line 13: activate: No such file or directory
Traceback (most recent call last):
  File "/home/choi/conda/anaconda3/envs/pytorchenv/lib/python3.8/site-packages/urllib3/connection.py", line 203, in _new_conn
    sock = connection.create_connection(
  File "/home/choi/conda/anaconda3/envs/pytorchenv/lib/python3.8/site-packages/urllib3/util/connection.py", line 60, in create_connection
    for res in socket.getaddrinfo(host, port, family, socket.SOCK_STREAM):
  File "/home/choi/conda/anaconda3/envs/pytorchenv/lib/python3.8/socket.py", line 918, in getaddrinfo
    for res in _socket.getaddrinfo(host, port, family, type, proto, flags):
socket.gaierror: [Errno -3] Temporary failure in name resolution

The above exception was the direct cause of the following exception:

Traceback (most recent call last):
  File "/home/choi/conda/anaconda3/envs/pytorchenv/lib/python3.8/site-packages/urllib3/connectionpool.py", line 790, in urlopen
    response = self._make_request(
  File "/home/choi/conda/anaconda3/envs/pytorchenv/lib/python3.8/site-packages/urllib3/connectionpool.py", line 491, in _make_request
    raise new_e
  File "/home/choi/conda/anaconda3/envs/pytorchenv/lib/python3.8/site-packages/urllib3/connectionpool.py", line 467, in _make_request
    self._validate_conn(conn)
  File "/home/choi/conda/anaconda3/envs/pytorchenv/lib/python3.8/site-packages/urllib3/connectionpool.py", line 1096, in _validate_conn
    conn.connect()
  File "/home/choi/conda/anaconda3/envs/pytorchenv/lib/python3.8/site-packages/urllib3/connection.py", line 611, in connect
    self.sock = sock = self._new_conn()
  File "/home/choi/conda/anaconda3/envs/pytorchenv/lib/python3.8/site-packages/urllib3/connection.py", line 210, in _new_conn
    raise NameResolutionError(self.host, self, e) from e
urllib3.exceptions.NameResolutionError: <urllib3.connection.HTTPSConnection object at 0x7f4b74f22670>: Failed to resolve 'huggingface.co' ([Errno -3] Temporary failure in name resolution)

The above exception was the direct cause of the following exception:

Traceback (most recent call last):
  File "/home/choi/conda/anaconda3/envs/pytorchenv/lib/python3.8/site-packages/requests/adapters.py", line 486, in send
    resp = conn.urlopen(
  File "/home/choi/conda/anaconda3/envs/pytorchenv/lib/python3.8/site-packages/urllib3/connectionpool.py", line 844, in urlopen
    retries = retries.increment(
  File "/home/choi/conda/anaconda3/envs/pytorchenv/lib/python3.8/site-packages/urllib3/util/retry.py", line 515, in increment
    raise MaxRetryError(_pool, url, reason) from reason  # type: ignore[arg-type]
urllib3.exceptions.MaxRetryError: HTTPSConnectionPool(host='huggingface.co', port=443): Max retries exceeded with url: /huggyllama/llama-7b/resolve/main/config.json (Caused by NameResolutionError("<urllib3.connection.HTTPSConnection object at 0x7f4b74f22670>: Failed to resolve 'huggingface.co' ([Errno -3] Temporary failure in name resolution)"))

During handling of the above exception, another exception occurred:

Traceback (most recent call last):
  File "/home/choi/conda/anaconda3/envs/pytorchenv/lib/python3.8/site-packages/huggingface_hub/file_download.py", line 1261, in hf_hub_download
    metadata = get_hf_file_metadata(
  File "/home/choi/conda/anaconda3/envs/pytorchenv/lib/python3.8/site-packages/huggingface_hub/utils/_validators.py", line 119, in _inner_fn
    return fn(*args, **kwargs)
  File "/home/choi/conda/anaconda3/envs/pytorchenv/lib/python3.8/site-packages/huggingface_hub/file_download.py", line 1674, in get_hf_file_metadata
    r = _request_wrapper(
  File "/home/choi/conda/anaconda3/envs/pytorchenv/lib/python3.8/site-packages/huggingface_hub/file_download.py", line 369, in _request_wrapper
    response = _request_wrapper(
  File "/home/choi/conda/anaconda3/envs/pytorchenv/lib/python3.8/site-packages/huggingface_hub/file_download.py", line 392, in _request_wrapper
    response = get_session().request(method=method, url=url, **params)
  File "/home/choi/conda/anaconda3/envs/pytorchenv/lib/python3.8/site-packages/requests/sessions.py", line 589, in request
    resp = self.send(prep, **send_kwargs)
  File "/home/choi/conda/anaconda3/envs/pytorchenv/lib/python3.8/site-packages/requests/sessions.py", line 703, in send
    r = adapter.send(request, **kwargs)
  File "/home/choi/conda/anaconda3/envs/pytorchenv/lib/python3.8/site-packages/huggingface_hub/utils/_http.py", line 68, in send
    return super().send(request, *args, **kwargs)
  File "/home/choi/conda/anaconda3/envs/pytorchenv/lib/python3.8/site-packages/requests/adapters.py", line 519, in send
    raise ConnectionError(e, request=request)
requests.exceptions.ConnectionError: (MaxRetryError('HTTPSConnectionPool(host=\'huggingface.co\', port=443): Max retries exceeded with url: /huggyllama/llama-7b/resolve/main/config.json (Caused by NameResolutionError("<urllib3.connection.HTTPSConnection object at 0x7f4b74f22670>: Failed to resolve \'huggingface.co\' ([Errno -3] Temporary failure in name resolution)"))'), '(Request ID: 3a52a7c9-b6da-4a78-87d8-d5dafa81d88d)')

The above exception was the direct cause of the following exception:

Traceback (most recent call last):
  File "/home/choi/conda/anaconda3/envs/pytorchenv/lib/python3.8/site-packages/transformers/utils/hub.py", line 417, in cached_file
    resolved_file = hf_hub_download(
  File "/home/choi/conda/anaconda3/envs/pytorchenv/lib/python3.8/site-packages/huggingface_hub/utils/_validators.py", line 119, in _inner_fn
    return fn(*args, **kwargs)
  File "/home/choi/conda/anaconda3/envs/pytorchenv/lib/python3.8/site-packages/huggingface_hub/file_download.py", line 1406, in hf_hub_download
    raise LocalEntryNotFoundError(
huggingface_hub.utils._errors.LocalEntryNotFoundError: An error happened while trying to locate the file on the Hub and we cannot find the requested files in the local cache. Please check your connection and try again or make sure your Internet connection is on.

During handling of the above exception, another exception occurred:

Traceback (most recent call last):
  File "run_main.py", line 135, in <module>
    model = TimeLLM.Model(args).float()
  File "/home/choi/TIMELLM/models/TimeLLM.py", line 46, in __init__
    self.llama_config = LlamaConfig.from_pretrained('huggyllama/llama-7b')
  File "/home/choi/conda/anaconda3/envs/pytorchenv/lib/python3.8/site-packages/transformers/configuration_utils.py", line 547, in from_pretrained
    config_dict, kwargs = cls.get_config_dict(pretrained_model_name_or_path, **kwargs)
  File "/home/choi/conda/anaconda3/envs/pytorchenv/lib/python3.8/site-packages/transformers/configuration_utils.py", line 574, in get_config_dict
    config_dict, kwargs = cls._get_config_dict(pretrained_model_name_or_path, **kwargs)
  File "/home/choi/conda/anaconda3/envs/pytorchenv/lib/python3.8/site-packages/transformers/configuration_utils.py", line 629, in _get_config_dict
    resolved_config_file = cached_file(
  File "/home/choi/conda/anaconda3/envs/pytorchenv/lib/python3.8/site-packages/transformers/utils/hub.py", line 452, in cached_file
    raise EnvironmentError(
OSError: We couldn't connect to 'https://huggingface.co' to load this file, couldn't find it in the cached files and it looks like huggyllama/llama-7b is not the path to a directory containing a file named config.json.
Checkout your internet connection or see how to run the library in offline mode at 'https://huggingface.co/docs/transformers/installation#offline-mode'.
srun: error: gpu-011: task 0: Exited with exit code 1
